Workbook

Sheet Lisez-moi
A1: Frise de l'art moderne (1874-1960) — base de données
A2: Préremplie à partir de la Bible de l'art (faits uniquement : noms, dates, œuvres). Les textes sont à rédiger par toi.
A4: Avancement
A5: Onglet | B5: Lignes | C5: Fiches rédigées | D5: % fiches
A6: Mouvements | B6: =COUNTA(Mouvements!A2:A301) -> 9 | C6: =COUNTIF(Mouvements!I2:I301,"rédigée") -> 9 | D6: =IF(B6=0,0,C6/B6) -> 1
A7: Artistes | B7: =COUNTA(Artistes!A2:A301) -> 34 | C7: =COUNTIF(Artistes!K2:K301,"rédigée") -> 34 | D7: =IF(B7=0,0,C7/B7) -> 1
A8: Œuvres | B8: =COUNTA(Œuvres!A2:A301) -> 104 | C8: =COUNTIF(Œuvres!O2:O301,"rédigée") -> 0 | D8: =IF(B8=0,0,C8/B8) -> 0
A9: Événements | B9: =COUNTA(Événements!A2:A301) -> 14
A10: Influences | B10: =COUNTA(Influences!A2:A301) -> 12
A13: Code couleur des en-têtes
B14: Données factuelles, préremplies : à vérifier et corriger si besoin.
B15: Texte court à rédiger toi-même.
B16: Calcul automatique : ne rien écrire.
B17: Cellule jaune dans « Notes » : une correction ou une décision à prendre sur cette ligne.
A19: Règles
A20: Identifiants | B20: En minuscules, sans accents, avec des tirets. Ils relient les onglets et donnent leur nom aux fiches (fauvisme → mouvements/fauvisme.md). Ne les change plus une fois utilisés.
A21: Résumé court ≠ fiche | B21: Le résumé (1 phrase) s'affiche sur la frise. Le contenu détaillé va dans la fiche Markdown du même identifiant.
A22: Statut fiche | B22: Passe-le à « rédigée » quand la fiche est terminée : le tableau d'avancement se met à jour.
A23: Œuvres hors bande | B23: Une œuvre peinte après la fin du mouvement (Guernica, Jazz…) tombera hors de la bande colorée. C'est normal : garde-la ou supprime-la selon ce que tu veux montrer.
A24: Œuvres majeures | B24: La colonne « Majeure (Bible) » repère les œuvres que tu avais toi-même mises en avant : bon point de départ pour décider quoi garder.
A25: Images | B25: Wikimedia Commons pour le domaine public, sinon lien vers la page du musée.

Sheet Mouvements
A1: ID | B1: Nom | C1: Début | D1: Fin | E1: Lieu | F1: Couleur | G1: Résumé court (1 phrase) | H1: Fichier fiche | I1: Statut fiche | J1: Nb artistes | K1: Nb œuvres | L1: Notes / corrections
A2: impressionnisme | B2: Impressionnisme | C2: 1874 | D2: 1886 | E2: France (Paris) | F2: #2874A6 | G2: Sortir de l’atelier pour saisir la lumière et l’instant. | H2: =IF(A2="","","mouvements/"&A2&".md") -> mouvements/impressionnisme.md | I2: rédigée | J2: =IF(A2="","",COUNTIF(Artistes!$G$2:$G$301,A2)) -> 5 | K2: =IF(A2="","",COUNTIF(Œuvres!$F$2:$F$301,A2)) -> 15 | L2: Bible : 1860-1890. Ramené à 1874 (1re exposition, début du périmètre) - 1886 (dernière exposition, citée dans ta Bible).
A3: post-impressionnisme | B3: Post-impressionnisme | C3: 1886 | D3: 1910 | E3: France | F3: #AF601A | G3: Après l’impressionnisme, chacun sa voie : la structure, l’émotion, le symbole ou la méthode. | H3: =IF(A3="","","mouvements/"&A3&".md") -> mouvements/post-impressionnisme.md | I3: rédigée | J3: =IF(A3="","",COUNTIF(Artistes!$G$2:$G$301,A3)) -> 4 | K3: =IF(A3="","",COUNTIF(Œuvres!$F$2:$F$301,A3)) -> 14 | L3: Bible : 1890-1910. Début avancé à 1886 : tes propres œuvres (Grande Jatte 1884-86, Mangeurs de pommes de terre 1885) précèdent 1890.
A4: fauvisme | B4: Fauvisme | C4: 1904 | D4: 1910 | E4: France | F4: #C0392B | G4: La couleur pure et éclatante, libérée de toute fidélité au réel. | H4: =IF(A4="","","mouvements/"&A4&".md") -> mouvements/fauvisme.md | I4: rédigée | J4: =IF(A4="","",COUNTIF(Artistes!$G$2:$G$301,A4)) -> 3 | K4: =IF(A4="","",COUNTIF(Œuvres!$F$2:$F$301,A4)) -> 12
A5: cubisme | B5: Cubisme | C5: 1907 | D5: 1914 | E5: France (Paris) | F5: #6E4E37 | G5: Décomposer l’objet en facettes pour le montrer sous tous ses angles à la fois. | H5: =IF(A5="","","mouvements/"&A5&".md") -> mouvements/cubisme.md | I5: rédigée | J5: =IF(A5="","",COUNTIF(Artistes!$G$2:$G$301,A5)) -> 3 | K5: =IF(A5="","",COUNTIF(Œuvres!$F$2:$F$301,A5)) -> 11
A6: expressionnisme | B6: Expressionnisme | C6: 1905 | D6: 1930 | E6: Allemagne | F6: #6C3483 | G6: Peindre ce que l’on ressent, et non ce que l’on voit. | H6: =IF(A6="","","mouvements/"&A6&".md") -> mouvements/expressionnisme.md | I6: rédigée | J6: =IF(A6="","",COUNTIF(Artistes!$G$2:$G$301,A6)) -> 3 | K6: =IF(A6="","",COUNTIF(Œuvres!$F$2:$F$301,A6)) -> 8
A7: abstraction | B7: Abstractionnisme | C7: 1910 | D7: 1944 | E7: Europe | F7: #117A65 | G7: La peinture renonce au réel : il ne reste que la couleur, la ligne et la forme. | H7: =IF(A7="","","mouvements/"&A7&".md") -> mouvements/abstraction.md | I7: rédigée | J7: =IF(A7="","",COUNTIF(Artistes!$G$2:$G$301,A7)) -> 4 | K7: =IF(A7="","",COUNTIF(Œuvres!$F$2:$F$301,A7)) -> 14 | L7: Bible : « Abstractionnisme (1910-?) ». Fin fixée à 1944 (mort de Kandinsky et Mondrian) : à ajuster.
A8: dadaisme | B8: Dadaïsme | C8: 1916 | D8: 1923 | E8: Zurich, Paris, Berlin, New York | F8: #566573 | G8: Une révolte contre la guerre, la raison et l’art lui-même. | H8: =IF(A8="","","mouvements/"&A8&".md") -> mouvements/dadaisme.md | I8: rédigée | J8: =IF(A8="","",COUNTIF(Artistes!$G$2:$G$301,A8)) -> 4 | K8: =IF(A8="","",COUNTIF(Œuvres!$F$2:$F$301,A8)) -> 12
A9: surrealisme | B9: Surréalisme | C9: 1924 | D9: 1940 | E9: France (Paris) | F9: #B03A72 | G9: Libérer l’inconscient, le rêve et le désir, hors de tout contrôle de la raison. | H9: =IF(A9="","","mouvements/"&A9&".md") -> mouvements/surrealisme.md | I9: rédigée | J9: =IF(A9="","",COUNTIF(Artistes!$G$2:$G$301,A9)) -> 4 | K9: =IF(A9="","",COUNTIF(Œuvres!$F$2:$F$301,A9)) -> 10 | L9: On date souvent la fin du mouvement à la mort de Breton (1966) ; 1940 (exil des surréalistes) reste défendable.
A10: expressionnisme-abstrait | B10: Expressionnisme abstrait | C10: 1943 | D10: 1960 | E10: États-Unis (New York) | F10: #154360 | G10: À New York, le geste et la couleur deviennent le sujet du tableau. | H10: =IF(A10="","","mouvements/"&A10&".md") -> mouvements/expressionnisme-abstrait.md | I10: rédigée | J10: =IF(A10="","",COUNTIF(Artistes!$G$2:$G$301,A10)) -> 4 | K10: =IF(A10="","",COUNTIF(Œuvres!$F$2:$F$301,A10)) -> 8
H11: =IF(A11="","","mouvements/"&A11&".md") | J11: =IF(A11="","",COUNTIF(Artistes!$G$2:$G$301,A11)) | K11: =IF(A11="","",COUNTIF(Œuvres!$F$2:$F$301,A11))
H12: =IF(A12="","","mouvements/"&A12&".md") | J12: =IF(A12="","",COUNTIF(Artistes!$G$2:$G$301,A12)) | K12: =IF(A12="","",COUNTIF(Œuvres!$F$2:$F$301,A12))
H13: =IF(A13="","","mouvements/"&A13&".md") | J13: =IF(A13="","",COUNTIF(Artistes!$G$2:$G$301,A13)) | K13: =IF(A13="","",COUNTIF(Œuvres!$F$2:$F$301,A13))
H14: =IF(A14="","","mouvements/"&A14&".md") | J14: =IF(A14="","",COUNTIF(Artistes!$G$2:$G$301,A14)) | K14: =IF(A14="","",COUNTIF(Œuvres!$F$2:$F$301,A14))
H15: =IF(A15="","","mouvements/"&A15&".md") | J15: =IF(A15="","",COUNTIF(Artistes!$G$2:$G$301,A15)) | K15: =IF(A15="","",COUNTIF(Œuvres!$F$2:$F$301,A15))
H16: =IF(A16="","","mouvements/"&A16&".md") | J16: =IF(A16="","",COUNTIF(Artistes!$G$2:$G$301,A16)) | K16: =IF(A16="","",COUNTIF(Œuvres!$F$2:$F$301,A16))
H17: =IF(A17="","","mouvements/"&A17&".md") | J17: =IF(A17="","",COUNTIF(Artistes!$G$2:$G$301,A17)) | K17: =IF(A17="","",COUNTIF(Œuvres!$F$2:$F$301,A17))
H18: =IF(A18="","","mouvements/"&A18&".md") | J18: =IF(A18="","",COUNTIF(Artistes!$G$2:$G$301,A18)) | K18: =IF(A18="","",COUNTIF(Œuvres!$F$2:$F$301,A18))
H19: =IF(A19="","","mouvements/"&A19&".md") | J19: =IF(A19="","",COUNTIF(Artistes!$G$2:$G$301,A19)) | K19: =IF(A19="","",COUNTIF(Œuvres!$F$2:$F$301,A19))
H20: =IF(A20="","","mouvements/"&A20&".md") | J20: =IF(A20="","",COUNTIF(Artistes!$G$2:$G$301,A20)) | K20: =IF(A20="","",COUNTIF(Œuvres!$F$2:$F$301,A20))
H21: =IF(A21="","","mouvements/"&A21&".md") | J21: =IF(A21="","",COUNTIF(Artistes!$G$2:$G$301,A21)) | K21: =IF(A21="","",COUNTIF(Œuvres!$F$2:$F$301,A21))
H22: =IF(A22="","","mouvements/"&A22&".md") | J22: =IF(A22="","",COUNTIF(Artistes!$G$2:$G$301,A22)) | K22: =IF(A22="","",COUNTIF(Œuvres!$F$2:$F$301,A22))
... H301: =IF(A301="","","mouvements/"&A301&".md") | J301: =IF(A301="","",COUNTIF(Artistes!$G$2:$G$301,A301)) | K301: =IF(A301="","",COUNTIF(Œuvres!$F$2:$F$301,A301))

Sheet Artistes
A1: ID | B1: Nom complet | C1: Naissance | D1: Décès | E1: Nationalité | F1: Rôle | G1: Mouvement principal | H1: Autres mouvements | I1: Phrase-clé (1 phrase) | J1: Fichier fiche | K1: Statut fiche | L1: Nb œuvres | M1: Domaine public ? | N1: Notes / corrections
A2: monet | B2: Claude Monet | C2: 1840 | D2: 1926 | E2: française | F2: peintre | G2: impressionnisme | I2: Le chef de file de l’impressionnisme, obsédé par les variations de la lumière. | J2: =IF(A2="","","artistes/"&A2&".md") -> artistes/monet.md | K2: rédigée | L2: =IF(A2="","",COUNTIF(Œuvres!$C$2:$C$301,A2)) -> 5 | M2: =IF(D2="","",IF(YEAR(TODAY())>=D2+71,"Oui (à vérifier)","Non")) -> Oui (à vérifier)
A3: renoir | B3: Pierre-Auguste Renoir | C3: 1841 | D3: 1919 | E3: française | F3: peintre | G3: impressionnisme | I3: Le peintre des figures et des moments heureux, baignés de lumière. | J3: =IF(A3="","","artistes/"&A3&".md") -> artistes/renoir.md | K3: rédigée | L3: =IF(A3="","",COUNTIF(Œuvres!$C$2:$C$301,A3)) -> 3 | M3: =IF(D3="","",IF(YEAR(TODAY())>=D3+71,"Oui (à vérifier)","Non")) -> Oui (à vérifier)
A4: degas | B4: Edgar Degas | C4: 1834 | D4: 1917 | E4: française | F4: peintre | G4: impressionnisme | I4: Le peintre du mouvement, des danseuses aux champs de courses. | J4: =IF(A4="","","artistes/"&A4&".md") -> artistes/degas.md | K4: rédigée | L4: =IF(A4="","",COUNTIF(Œuvres!$C$2:$C$301,A4)) -> 3 | M4: =IF(D4="","",IF(YEAR(TODAY())>=D4+71,"Oui (à vérifier)","Non")) -> Oui (à vérifier)
A5: pissarro | B5: Camille Pissarro | C5: 1830 | D5: 1903 | E5: franco-danoise (né aux Antilles danoises) | F5: peintre | G5: impressionnisme | H5: post-impressionnisme | I5: Le doyen et le mentor du groupe, seul présent aux huit expositions. | J5: =IF(A5="","","artistes/"&A5&".md") -> artistes/pissarro.md | K5: rédigée | L5: =IF(A5="","",COUNTIF(Œuvres!$C$2:$C$301,A5)) -> 3 | M5: =IF(D5="","",IF(YEAR(TODAY())>=D5+71,"Oui (à vérifier)","Non")) -> Oui (à vérifier)
A6: morisot | B6: Berthe Morisot | C6: 1841 | D6: 1895 | E6: française | F6: peintre | G6: impressionnisme | I6: La première femme du groupe impressionniste, peintre de l’intimité. | J6: =IF(A6="","","artistes/"&A6&".md") -> artistes/morisot.md | K6: rédigée | L6: =IF(A6="","",COUNTIF(Œuvres!$C$2:$C$301,A6)) -> 1 | M6: =IF(D6="","",IF(YEAR(TODAY())>=D6+71,"Oui (à vérifier)","Non")) -> Oui (à vérifier) | N6: Ajoutée : citée dans tes œuvres majeures sans fiche.
A7: van-gogh | B7: Vincent van Gogh | C7: 1853 | D7: 1890 | E7: néerlandaise | F7: peintre | G7: post-impressionnisme | I7: La couleur comme langage des émotions. | J7: =IF(A7="","","artistes/"&A7&".md") -> artistes/van-gogh.md | K7: rédigée | L7: =IF(A7="","",COUNTIF(Œuvres!$C$2:$C$301,A7)) -> 4 | M7: =IF(D7="","",IF(YEAR(TODAY())>=D7+71,"Oui (à vérifier)","Non")) -> Oui (à vérifier)
A8: cezanne | B8: Paul Cézanne | C8: 1839 | D8: 1906 | E8: française | F8: peintre | G8: post-impressionnisme | H8: impressionnisme | I8: Le « père de l’art moderne », qui construit la nature par volumes. | J8: =IF(A8="","","artistes/"&A8&".md") -> artistes/cezanne.md | K8: rédigée | L8: =IF(A8="","",COUNTIF(Œuvres!$C$2:$C$301,A8)) -> 4 | M8: =IF(D8="","",IF(YEAR(TODAY())>=D8+71,"Oui (à vérifier)","Non")) -> Oui (à vérifier)
A9: gauguin | B9: Paul Gauguin | C9: 1848 | D9: 1903 | E9: française | F9: peintre | G9: post-impressionnisme | I9: Des aplats de couleur symboliques, et un ailleurs rêvé jusqu’en Polynésie. | J9: =IF(A9="","","artistes/"&A9&".md") -> artistes/gauguin.md | K9: rédigée | L9: =IF(A9="","",COUNTIF(Œuvres!$C$2:$C$301,A9)) -> 3 | M9: =IF(D9="","",IF(YEAR(TODAY())>=D9+71,"Oui (à vérifier)","Non")) -> Oui (à vérifier)
A10: seurat | B10: Georges Seurat | C10: 1859 | D10: 1891 | E10: française | F10: peintre | G10: post-impressionnisme | H10: néo-impressionnisme | I10: L’inventeur du pointillisme, qui peint avec la science des couleurs. | J10: =IF(A10="","","artistes/"&A10&".md") -> artistes/seurat.md | K10: rédigée | L10: =IF(A10="","",COUNTIF(Œuvres!$C$2:$C$301,A10)) -> 3 | M10: =IF(D10="","",IF(YEAR(TODAY())>=D10+71,"Oui (à vérifier)","Non")) -> Oui (à vérifier)
A11: matisse | B11: Henri Matisse | C11: 1869 | D11: 1954 | E11: française | F11: peintre | G11: fauvisme | I11: Le chef de file des fauves, qui a fait de la couleur une libération. | J11: =IF(A11="","","artistes/"&A11&".md") -> artistes/matisse.md | K11: rédigée | L11: =IF(A11="","",COUNTIF(Œuvres!$C$2:$C$301,A11)) -> 6 | M11: =IF(D11="","",IF(YEAR(TODAY())>=D11+71,"Oui (à vérifier)","Non")) -> Oui (à vérifier)
A12: derain | B12: André Derain | C12: 1880 | D12: 1954 | E12: française | F12: peintre | G12: fauvisme | I12: Le fauve des contrastes violents, revenu ensuite à la tradition. | J12: =IF(A12="","","artistes/"&A12&".md") -> artistes/derain.md | K12: rédigée | L12: =IF(A12="","",COUNTIF(Œuvres!$C$2:$C$301,A12)) -> 3 | M12: =IF(D12="","",IF(YEAR(TODAY())>=D12+71,"Oui (à vérifier)","Non")) -> Oui (à vérifier)
A13: vlaminck | B13: Maurice de Vlaminck | C13: 1876 | D13: 1958 | E13: française | F13: peintre | G13: fauvisme | I13: Le plus fougueux des fauves, qui peignait avec la couleur sortie du tube. | J13: =IF(A13="","","artistes/"&A13&".md") -> artistes/vlaminck.md | K13: rédigée | L13: =IF(A13="","",COUNTIF(Œuvres!$C$2:$C$301,A13)) -> 3 | M13: =IF(D13="","",IF(YEAR(TODAY())>=D13+71,"Oui (à vérifier)","Non")) -> Non
A14: picasso | B14: Pablo Picasso | C14: 1881 | D14: 1973 | E14: espagnole | F14: peintre | G14: cubisme | H14: surréalisme (proche) | I14: Le cofondateur du cubisme, qui n’a jamais cessé de se réinventer. | J14: =IF(A14="","","artistes/"&A14&".md") -> artistes/picasso.md | K14: rédigée | L14: =IF(A14="","",COUNTIF(Œuvres!$C$2:$C$301,A14)) -> 4 | M14: =IF(D14="","",IF(YEAR(TODAY())>=D14+71,"Oui (à vérifier)","Non")) -> Non
A15: braque | B15: Georges Braque | C15: 1882 | D15: 1963 | E15: française | F15: peintre | G15: cubisme | H15: fauvisme | I15: L’autre inventeur du cubisme, peintre de l’équilibre et de la mesure. | J15: =IF(A15="","","artistes/"&A15&".md") -> artistes/braque.md | K15: rédigée | L15: =IF(A15="","",COUNTIF(Œuvres!$C$2:$C$301,A15)) -> 4 | M15: =IF(D15="","",IF(YEAR(TODAY())>=D15+71,"Oui (à vérifier)","Non")) -> Non
A16: gris | B16: Juan Gris | C16: 1887 | D16: 1927 | E16: espagnole | F16: peintre | G16: cubisme | I16: Le plus rigoureux des cubistes, architecte de toiles parfaitement équilibrées. | J16: =IF(A16="","","artistes/"&A16&".md") -> artistes/gris.md | K16: rédigée | L16: =IF(A16="","",COUNTIF(Œuvres!$C$2:$C$301,A16)) -> 3 | M16: =IF(D16="","",IF(YEAR(TODAY())>=D16+71,"Oui (à vérifier)","Non")) -> Oui (à vérifier)
A17: kirchner | B17: Ernst Ludwig Kirchner | C17: 1880 | D17: 1938 | E17: allemande | F17: peintre | G17: expressionnisme | I17: Le fondateur de Die Brücke, peintre de la fièvre de la ville moderne. | J17: =IF(A17="","","artistes/"&A17&".md") -> artistes/kirchner.md | K17: rédigée | L17: =IF(A17="","",COUNTIF(Œuvres!$C$2:$C$301,A17)) -> 3 | M17: =IF(D17="","",IF(YEAR(TODAY())>=D17+71,"Oui (à vérifier)","Non")) -> Oui (à vérifier) | N17: Dates complétées (absentes de ta Bible).
A18: nolde | B18: Emil Nolde | C18: 1867 | D18: 1956 | E18: allemande (citoyen danois après 1920) | F18: peintre | G18: expressionnisme | I18: Un maître de la couleur brute, à l’engagement nazi longtemps caché. | J18: =IF(A18="","","artistes/"&A18&".md") -> artistes/nolde.md | K18: rédigée | L18: =IF(A18="","",COUNTIF(Œuvres!$C$2:$C$301,A18)) -> 2 | M18: =IF(D18="","",IF(YEAR(TODAY())>=D18+71,"Oui (à vérifier)","Non")) -> Non | N18: Ta Bible dit « peintre danois » : il est considéré comme un peintre allemand, devenu citoyen danois quand sa région natale est rattachée au Danemark en 1920.
A19: marc | B19: Franz Marc | C19: 1880 | D19: 1916 | E19: allemande | F19: peintre | G19: expressionnisme | I19: Les animaux et la couleur symbolique, miroirs d’une harmonie perdue. | J19: =IF(A19="","","artistes/"&A19&".md") -> artistes/marc.md | K19: rédigée | L19: =IF(A19="","",COUNTIF(Œuvres!$C$2:$C$301,A19)) -> 3 | M19: =IF(D19="","",IF(YEAR(TODAY())>=D19+71,"Oui (à vérifier)","Non")) -> Oui (à vérifier)
A20: kandinsky | B20: Vassily Kandinsky | C20: 1866 | D20: 1944 | E20: russe (puis allemande, puis française) | F20: peintre, théoricien | G20: abstraction | H20: expressionnisme | I20: Le grand théoricien de l’abstraction, qui voulait peindre la musique. | J20: =IF(A20="","","artistes/"&A20&".md") -> artistes/kandinsky.md | K20: rédigée | L20: =IF(A20="","",COUNTIF(Œuvres!$C$2:$C$301,A20)) -> 4 | M20: =IF(D20="","",IF(YEAR(TODAY())>=D20+71,"Oui (à vérifier)","Non")) -> Oui (à vérifier)
A21: malevitch | B21: Kasimir Malevitch | C21: 1879 | D21: 1935 | E21: russe (né à Kiev) | F21: peintre, théoricien | G21: abstraction | I21: L’inventeur du suprématisme et de son célèbre carré noir. | J21: =IF(A21="","","artistes/"&A21&".md") -> artistes/malevitch.md | K21: rédigée | L21: =IF(A21="","",COUNTIF(Œuvres!$C$2:$C$301,A21)) -> 4 | M21: =IF(D21="","",IF(YEAR(TODAY())>=D21+71,"Oui (à vérifier)","Non")) -> Oui (à vérifier)
A22: mondrian | B22: Piet Mondrian | C22: 1872 | D22: 1944 | E22: néerlandaise | F22: peintre, théoricien | G22: abstraction | I22: L’abstraction réduite à des lignes droites et à quelques couleurs pures. | J22: =IF(A22="","","artistes/"&A22&".md") -> artistes/mondrian.md | K22: rédigée | L22: =IF(A22="","",COUNTIF(Œuvres!$C$2:$C$301,A22)) -> 3 | M22: =IF(D22="","",IF(YEAR(TODAY())>=D22+71,"Oui (à vérifier)","Non")) -> Oui (à vérifier)
A23: kupka | B23: František Kupka | C23: 1871 | D23: 1957 | E23: tchèque | F23: peintre | G23: abstraction | I23: Le premier à exposer des toiles abstraites à Paris, en 1912. | J23: =IF(A23="","","artistes/"&A23&".md") -> artistes/kupka.md | K23: rédigée | L23: =IF(A23="","",COUNTIF(Œuvres!$C$2:$C$301,A23)) -> 3 | M23: =IF(D23="","",IF(YEAR(TODAY())>=D23+71,"Oui (à vérifier)","Non")) -> Non
A24: tzara | B24: Tristan Tzara | C24: 1896 | D24: 1963 | E24: roumaine (puis française) | F24: poète, théoricien | G24: dadaisme | H24: surréalisme | I24: La voix de Dada et l’auteur de ses manifestes. | J24: =IF(A24="","","artistes/"&A24&".md") -> artistes/tzara.md | K24: rédigée | L24: =IF(A24="","",COUNTIF(Œuvres!$C$2:$C$301,A24)) -> 3 | M24: =IF(D24="","",IF(YEAR(TODAY())>=D24+71,"Oui (à vérifier)","Non")) -> Non
A25: arp | B25: Hans Arp | C25: 1886 | D25: 1966 | E25: franco-allemande (alsacien) | F25: peintre, sculpteur, poète | G25: dadaisme | H25: surréalisme | I25: Le hasard érigé en méthode, entre Dada, surréalisme et abstraction. | J25: =IF(A25="","","artistes/"&A25&".md") -> artistes/arp.md | K25: rédigée | L25: =IF(A25="","",COUNTIF(Œuvres!$C$2:$C$301,A25)) -> 3 | M25: =IF(D25="","",IF(YEAR(TODAY())>=D25+71,"Oui (à vérifier)","Non")) -> Non
A26: picabia | B26: Francis Picabia | C26: 1879 | D26: 1953 | E26: française | F26: peintre | G26: dadaisme | I26: Le touche-à-tout insaisissable qui a poussé Dada à rire de tout. | J26: =IF(A26="","","artistes/"&A26&".md") -> artistes/picabia.md | K26: rédigée | L26: =IF(A26="","",COUNTIF(Œuvres!$C$2:$C$301,A26)) -> 4 | M26: =IF(D26="","",IF(YEAR(TODAY())>=D26+71,"Oui (à vérifier)","Non")) -> Oui (à vérifier)
A27: duchamp | B27: Marcel Duchamp | C27: 1887 | D27: 1968 | E27: française (puis américaine) | F27: artiste | G27: dadaisme | I27: L’inventeur du ready-made, qui a fait du regard le cœur de l’œuvre. | J27: =IF(A27="","","artistes/"&A27&".md") -> artistes/duchamp.md | K27: rédigée | L27: =IF(A27="","",COUNTIF(Œuvres!$C$2:$C$301,A27)) -> 2 | M27: =IF(D27="","",IF(YEAR(TODAY())>=D27+71,"Oui (à vérifier)","Non")) -> Non | N27: Ajouté : cité dans tes œuvres majeures sans fiche.
A28: breton | B28: André Breton | C28: 1896 | D28: 1966 | E28: française | F28: poète, théoricien | G28: surrealisme | H28: dadaisme | I28: Le fondateur et chef d’orchestre du surréalisme. | J28: =IF(A28="","","artistes/"&A28&".md") -> artistes/breton.md | K28: rédigée | L28: =IF(A28="","",COUNTIF(Œuvres!$C$2:$C$301,A28)) -> 3 | M28: =IF(D28="","",IF(YEAR(TODAY())>=D28+71,"Oui (à vérifier)","Non")) -> Non
A29: dali | B29: Salvador Dalí | C29: 1904 | D29: 1989 | E29: espagnole | F29: peintre | G29: surrealisme | I29: Le surréaliste virtuose, qui peint ses rêves avec la précision d’un maître ancien. | J29: =IF(A29="","","artistes/"&A29&".md") -> artistes/dali.md | K29: rédigée | L29: =IF(A29="","",COUNTIF(Œuvres!$C$2:$C$301,A29)) -> 4 | M29: =IF(D29="","",IF(YEAR(TODAY())>=D29+71,"Oui (à vérifier)","Non")) -> Non
A30: ernst | B30: Max Ernst | C30: 1891 | D30: 1976 | E30: allemande (puis américaine, puis française) | F30: peintre | G30: surrealisme | H30: dadaisme | I30: L’inventeur du frottage et des créatures hybrides, entre Dada et surréalisme. | J30: =IF(A30="","","artistes/"&A30&".md") -> artistes/ernst.md | K30: rédigée | L30: =IF(A30="","",COUNTIF(Œuvres!$C$2:$C$301,A30)) -> 2 | M30: =IF(D30="","",IF(YEAR(TODAY())>=D30+71,"Oui (à vérifier)","Non")) -> Non
A31: magritte | B31: René Magritte | C31: 1898 | D31: 1967 | E31: belge | F31: peintre | G31: surrealisme | I31: Des images parfaitement nettes pour semer le doute sur ce que l’on voit. | J31: =IF(A31="","","artistes/"&A31&".md") -> artistes/magritte.md | K31: rédigée | L31: =IF(A31="","",COUNTIF(Œuvres!$C$2:$C$301,A31)) -> 1 | M31: =IF(D31="","",IF(YEAR(TODAY())>=D31+71,"Oui (à vérifier)","Non")) -> Non | N31: Ajouté : cité dans tes œuvres majeures sans fiche.
A32: pollock | B32: Jackson Pollock | C32: 1912 | D32: 1956 | E32: américaine | F32: peintre | G32: expressionnisme-abstrait | I32: La toile posée au sol, et la peinture devenue la trace d’une danse. | J32: =IF(A32="","","artistes/"&A32&".md") -> artistes/pollock.md | K32: rédigée | L32: =IF(A32="","",COUNTIF(Œuvres!$C$2:$C$301,A32)) -> 3 | M32: =IF(D32="","",IF(YEAR(TODAY())>=D32+71,"Oui (à vérifier)","Non")) -> Non
A33: rothko | B33: Mark Rothko | C33: 1903 | D33: 1970 | E33: américaine (né en Russie) | F33: peintre | G33: expressionnisme-abstrait | I33: De grands rectangles de couleur pour une expérience presque spirituelle. | J33: =IF(A33="","","artistes/"&A33&".md") -> artistes/rothko.md | K33: rédigée | L33: =IF(A33="","",COUNTIF(Œuvres!$C$2:$C$301,A33)) -> 3 | M33: =IF(D33="","",IF(YEAR(TODAY())>=D33+71,"Oui (à vérifier)","Non")) -> Non
A34: newman | B34: Barnett Newman | C34: 1905 | D34: 1970 | E34: américaine | F34: peintre | G34: expressionnisme-abstrait | I34: De vastes champs de couleur traversés par ses fameux « zips ». | J34: =IF(A34="","","artistes/"&A34&".md") -> artistes/newman.md | K34: rédigée | L34: =IF(A34="","",COUNTIF(Œuvres!$C$2:$C$301,A34)) -> 1 | M34: =IF(D34="","",IF(YEAR(TODAY())>=D34+71,"Oui (à vérifier)","Non")) -> Non | N34: Fiche inachevée dans ta Bible (« WIP »).
A35: de-kooning | B35: Willem de Kooning | C35: 1904 | D35: 1997 | E35: américaine (né aux Pays-Bas) | F35: peintre | G35: expressionnisme-abstrait | I35: La figure humaine surgie du chaos de l’action painting. | J35: =IF(A35="","","artistes/"&A35&".md") -> artistes/de-kooning.md | K35: rédigée | L35: =IF(A35="","",COUNTIF(Œuvres!$C$2:$C$301,A35)) -> 1 | M35: =IF(D35="","",IF(YEAR(TODAY())>=D35+71,"Oui (à vérifier)","Non")) -> Non | N35: Ajouté : cité dans tes œuvres majeures sans fiche.
J36: =IF(A36="","","artistes/"&A36&".md") | L36: =IF(A36="","",COUNTIF(Œuvres!$C$2:$C$301,A36)) | M36: =IF(D36="","",IF(YEAR(TODAY())>=D36+71,"Oui (à vérifier)","Non"))
J37: =IF(A37="","","artistes/"&A37&".md") | L37: =IF(A37="","",COUNTIF(Œuvres!$C$2:$C$301,A37)) | M37: =IF(D37="","",IF(YEAR(TODAY())>=D37+71,"Oui (à vérifier)","Non"))
J38: =IF(A38="","","artistes/"&A38&".md") | L38: =IF(A38="","",COUNTIF(Œuvres!$C$2:$C$301,A38)) | M38: =IF(D38="","",IF(YEAR(TODAY())>=D38+71,"Oui (à vérifier)","Non"))
J39: =IF(A39="","","artistes/"&A39&".md") | L39: =IF(A39="","",COUNTIF(Œuvres!$C$2:$C$301,A39)) | M39: =IF(D39="","",IF(YEAR(TODAY())>=D39+71,"Oui (à vérifier)","Non"))
J40: =IF(A40="","","artistes/"&A40&".md") | L40: =IF(A40="","",COUNTIF(Œuvres!$C$2:$C$301,A40)) | M40: =IF(D40="","",IF(YEAR(TODAY())>=D40+71,"Oui (à vérifier)","Non"))
...

Sheet Œuvres
A1: ID | B1: Titre | C1: Artiste (ID) | D1: Artiste | E1: Année | F1: Mouvement | G1: Date affichée | H1: Type | I1: Musée | J1: Ville | K1: Majeure (Bible) | L1: Lien image | M1: Résumé court (1 phrase) | N1: Fichier fiche | O1: Statut fiche | P1: Domaine public ? | Q1: Notes / corrections
A2: impression-soleil-levant | B2: Impression, soleil levant | C2: monet | D2: =IF(C2="","",IFERROR(INDEX(Artistes!$B$2:$B$301,MATCH(C2,Artistes!$A$2:$A$301,0)),"ID inconnu")) -> Claude Monet | E2: 1872 | F2: impressionnisme | H2: peinture | I2: Musée Marmottan Monet | J2: Paris | K2: oui | L2: images/impression-soleil-levant.jpg | N2: =IF(A2="","","oeuvres/"&A2&".md") -> oeuvres/impression-soleil-levant.md | O2: à rédiger | P2: =IF(C2="","",IFERROR(INDEX(Artistes!$M$2:$M$301,MATCH(C2,Artistes!$A$2:$A$301,0)),"")) -> Oui (à vérifier) | Q2: Antérieure à 1874 mais exposée en 1874 : à garder.
A3: la-gare-saint-lazare | B3: La Gare Saint-Lazare | C3: monet | D3: =IF(C3="","",IFERROR(INDEX(Artistes!$B$2:$B$301,MATCH(C3,Artistes!$A$2:$A$301,0)),"ID inconnu")) -> Claude Monet | E3: 1877 | F3: impressionnisme | G3: série, 1877 | H3: peinture | I3: Musée d'Orsay (une version) | J3: Paris | N3: =IF(A3="","","oeuvres/"&A3&".md") -> oeuvres/la-gare-saint-lazare.md | O3: à rédiger | P3: =IF(C3="","",IFERROR(INDEX(Artistes!$M$2:$M$301,MATCH(C3,Artistes!$A$2:$A$301,0)),"")) -> Oui (à vérifier)
A4: falaises-a-etretat | B4: Falaises à Étretat | C4: monet | D4: =IF(C4="","",IFERROR(INDEX(Artistes!$B$2:$B$301,MATCH(C4,Artistes!$A$2:$A$301,0)),"ID inconnu")) -> Claude Monet | E4: 1883 | F4: impressionnisme | G4: 1883-1886 | H4: peinture | N4: =IF(A4="","","oeuvres/"&A4&".md") -> oeuvres/falaises-a-etretat.md | O4: à rédiger | P4: =IF(C4="","",IFERROR(INDEX(Artistes!$M$2:$M$301,MATCH(C4,Artistes!$A$2:$A$301,0)),"")) -> Oui (à vérifier)
A5: cathedrales-de-rouen | B5: Cathédrales de Rouen | C5: monet | D5: =IF(C5="","",IFERROR(INDEX(Artistes!$B$2:$B$301,MATCH(C5,Artistes!$A$2:$A$301,0)),"ID inconnu")) -> Claude Monet | E5: 1892 | F5: impressionnisme | G5: série, 1892-1894 | H5: peinture | N5: =IF(A5="","","oeuvres/"&A5&".md") -> oeuvres/cathedrales-de-rouen.md | O5: à rédiger | P5: =IF(C5="","",IFERROR(INDEX(Artistes!$M$2:$M$301,MATCH(C5,Artistes!$A$2:$A$301,0)),"")) -> Oui (à vérifier) | Q5: Ta fiche Monet dit 1894 et ta liste 1892-1894 : la série est peinte en 1892-1893 et retouchée en 1894.
A6: les-nympheas | B6: Les Nymphéas | C6: monet | D6: =IF(C6="","",IFERROR(INDEX(Artistes!$B$2:$B$301,MATCH(C6,Artistes!$A$2:$A$301,0)),"ID inconnu")) -> Claude Monet | E6: 1899 | F6: impressionnisme | G6: vers 1897-1926 | H6: peinture | I6: Musée de l'Orangerie (grand cycle) | J6: Paris | N6: =IF(A6="","","oeuvres/"&A6&".md") -> oeuvres/les-nympheas.md | O6: à rédiger | P6: =IF(C6="","",IFERROR(INDEX(Artistes!$M$2:$M$301,MATCH(C6,Artistes!$A$2:$A$301,0)),"")) -> Oui (à vérifier)
A7: le-bal-du-moulin-de-la-galette | B7: Le Bal du moulin de la Galette | C7: renoir | D7: =IF(C7="","",IFERROR(INDEX(Artistes!$B$2:$B$301,MATCH(C7,Artistes!$A$2:$A$301,0)),"ID inconnu")) -> Pierre-Auguste Renoir | E7: 1876 | F7: impressionnisme | H7: peinture | I7: Musée d'Orsay | J7: Paris | N7: =IF(A7="","","oeuvres/"&A7&".md") -> oeuvres/le-bal-du-moulin-de-la-galette.md | O7: à rédiger | P7: =IF(C7="","",IFERROR(INDEX(Artistes!$M$2:$M$301,MATCH(C7,Artistes!$A$2:$A$301,0)),"")) -> Oui (à vérifier)
A8: le-dejeuner-des-canotiers | B8: Le Déjeuner des canotiers | C8: renoir | D8: =IF(C8="","",IFERROR(INDEX(Artistes!$B$2:$B$301,MATCH(C8,Artistes!$A$2:$A$301,0)),"ID inconnu")) -> Pierre-Auguste Renoir | E8: 1881 | F8: impressionnisme | G8: 1880-1881 | H8: peinture | I8: Phillips Collection | J8: Washington | K8: oui | N8: =IF(A8="","","oeuvres/"&A8&".md") -> oeuvres/le-dejeuner-des-canotiers.md | O8: à rédiger | P8: =IF(C8="","",IFERROR(INDEX(Artistes!$M$2:$M$301,MATCH(C8,Artistes!$A$2:$A$301,0)),"")) -> Oui (à vérifier)
A9: la-danse-a-bougival | B9: La Danse à Bougival | C9: renoir | D9: =IF(C9="","",IFERROR(INDEX(Artistes!$B$2:$B$301,MATCH(C9,Artistes!$A$2:$A$301,0)),"ID inconnu")) -> Pierre-Auguste Renoir | E9: 1883 | F9: impressionnisme | H9: peinture | I9: Museum of Fine Arts | J9: Boston | N9: =IF(A9="","","oeuvres/"&A9&".md") -> oeuvres/la-danse-a-bougival.md | O9: à rédiger | P9: =IF(C9="","",IFERROR(INDEX(Artistes!$M$2:$M$301,MATCH(C9,Artistes!$A$2:$A$301,0)),"")) -> Oui (à vérifier)
A10: la-classe-de-danse | B10: La Classe de danse | C10: degas | D10: =IF(C10="","",IFERROR(INDEX(Artistes!$B$2:$B$301,MATCH(C10,Artistes!$A$2:$A$301,0)),"ID inconnu")) -> Edgar Degas | E10: 1874 | F10: impressionnisme | G10: vers 1873-1876 | H10: peinture | I10: Musée d'Orsay | J10: Paris | N10: =IF(A10="","","oeuvres/"&A10&".md") -> oeuvres/la-classe-de-danse.md | O10: à rédiger | P10: =IF(C10="","",IFERROR(INDEX(Artistes!$M$2:$M$301,MATCH(C10,Artistes!$A$2:$A$301,0)),"")) -> Oui (à vérifier) | Q10: Ta Bible : 1871-1874. Le musée d'Orsay date sa version de 1873-1876.
A11: l-absinthe | B11: L'Absinthe | C11: degas | D11: =IF(C11="","",IFERROR(INDEX(Artistes!$B$2:$B$301,MATCH(C11,Artistes!$A$2:$A$301,0)),"ID inconnu")) -> Edgar Degas | E11: 1876 | F11: impressionnisme | G11: 1875-1876 | H11: peinture | I11: Musée d'Orsay | J11: Paris | N11: =IF(A11="","","oeuvres/"&A11&".md") -> oeuvres/l-absinthe.md | O11: à rédiger | P11: =IF(C11="","",IFERROR(INDEX(Artistes!$M$2:$M$301,MATCH(C11,Artistes!$A$2:$A$301,0)),"")) -> Oui (à vérifier)
A12: danseuses-bleues | B12: Danseuses bleues | C12: degas | D12: =IF(C12="","",IFERROR(INDEX(Artistes!$B$2:$B$301,MATCH(C12,Artistes!$A$2:$A$301,0)),"ID inconnu")) -> Edgar Degas | E12: 1897 | F12: impressionnisme | H12: peinture | N12: =IF(A12="","","oeuvres/"&A12&".md") -> oeuvres/danseuses-bleues.md | O12: à rédiger | P12: =IF(C12="","",IFERROR(INDEX(Artistes!$M$2:$M$301,MATCH(C12,Artistes!$A$2:$A$301,0)),"")) -> Oui (à vérifier) | Q12: Plusieurs versions existent : à préciser.
A13: les-bords-de-l-oise-a-pontoise | B13: Les Bords de l'Oise à Pontoise | C13: pissarro | D13: =IF(C13="","",IFERROR(INDEX(Artistes!$B$2:$B$301,MATCH(C13,Artistes!$A$2:$A$301,0)),"ID inconnu")) -> Camille Pissarro | E13: 1867 | F13: impressionnisme | H13: peinture | N13: =IF(A13="","","oeuvres/"&A13&".md") -> oeuvres/les-bords-de-l-oise-a-pontoise.md | O13: à rédiger | P13: =IF(C13="","",IFERROR(INDEX(Artistes!$M$2:$M$301,MATCH(C13,Artistes!$A$2:$A$301,0)),"")) -> Oui (à vérifier) | Q13: Antérieure à 1874 : à garder ou non.
A14: printemps-pruniers-en-fleurs | B14: Printemps. Pruniers en fleurs | C14: pissarro | D14: =IF(C14="","",IFERROR(INDEX(Artistes!$B$2:$B$301,MATCH(C14,Artistes!$A$2:$A$301,0)),"ID inconnu")) -> Camille Pissarro | E14: 1877 | F14: impressionnisme | H14: peinture | I14: Musée d'Orsay | J14: Paris | N14: =IF(A14="","","oeuvres/"&A14&".md") -> oeuvres/printemps-pruniers-en-fleurs.md | O14: à rédiger | P14: =IF(C14="","",IFERROR(INDEX(Artistes!$M$2:$M$301,MATCH(C14,Artistes!$A$2:$A$301,0)),"")) -> Oui (à vérifier)
A15: soleil-levant-a-eragny | B15: Soleil levant à Éragny | C15: pissarro | D15: =IF(C15="","",IFERROR(INDEX(Artistes!$B$2:$B$301,MATCH(C15,Artistes!$A$2:$A$301,0)),"ID inconnu")) -> Camille Pissarro | E15: 1894 | F15: impressionnisme | H15: peinture | N15: =IF(A15="","","oeuvres/"&A15&".md") -> oeuvres/soleil-levant-a-eragny.md | O15: à rédiger | P15: =IF(C15="","",IFERROR(INDEX(Artistes!$M$2:$M$301,MATCH(C15,Artistes!$A$2:$A$301,0)),"")) -> Oui (à vérifier)
A16: le-berceau | B16: Le Berceau | C16: morisot | D16: =IF(C16="","",IFERROR(INDEX(Artistes!$B$2:$B$301,MATCH(C16,Artistes!$A$2:$A$301,0)),"ID inconnu")) -> Berthe Morisot | E16: 1872 | F16: impressionnisme | H16: peinture | I16: Musée d'Orsay | J16: Paris | K16: oui | N16: =IF(A16="","","oeuvres/"&A16&".md") -> oeuvres/le-berceau.md | O16: à rédiger | P16: =IF(C16="","",IFERROR(INDEX(Artistes!$M$2:$M$301,MATCH(C16,Artistes!$A$2:$A$301,0)),"")) -> Oui (à vérifier) | Q16: Exposée en 1874 à la première exposition impressionniste.
A17: les-mangeurs-de-pommes-de-terre | B17: Les Mangeurs de pommes de terre | C17: van-gogh | D17: =IF(C17="","",IFERROR(INDEX(Artistes!$B$2:$B$301,MATCH(C17,Artistes!$A$2:$A$301,0)),"ID inconnu")) -> Vincent van Gogh | E17: 1885 | F17: post-impressionnisme | H17: peinture | I17: Van Gogh Museum | J17: Amsterdam | N17: =IF(A17="","","oeuvres/"&A17&".md") -> oeuvres/les-mangeurs-de-pommes-de-terre.md | O17: à rédiger | P17: =IF(C17="","",IFERROR(INDEX(Artistes!$M$2:$M$301,MATCH(C17,Artistes!$A$2:$A$301,0)),"")) -> Oui (à vérifier)
A18: tournesols | B18: Tournesols | C18: van-gogh | D18: =IF(C18="","",IFERROR(INDEX(Artistes!$B$2:$B$301,MATCH(C18,Artistes!$A$2:$A$301,0)),"ID inconnu")) -> Vincent van Gogh | E18: 1888 | F18: post-impressionnisme | G18: série, 1888-1889 | H18: peinture | I18: National Gallery (une version) | J18: Londres | N18: =IF(A18="","","oeuvres/"&A18&".md") -> oeuvres/tournesols.md | O18: à rédiger | P18: =IF(C18="","",IFERROR(INDEX(Artistes!$M$2:$M$301,MATCH(C18,Artistes!$A$2:$A$301,0)),"")) -> Oui (à vérifier)
A19: la-chambre-a-arles | B19: La Chambre à Arles | C19: van-gogh | D19: =IF(C19="","",IFERROR(INDEX(Artistes!$B$2:$B$301,MATCH(C19,Artistes!$A$2:$A$301,0)),"ID inconnu")) -> Vincent van Gogh | E19: 1888 | F19: post-impressionnisme | H19: peinture | I19: Van Gogh Museum (1re version) | J19: Amsterdam | K19: oui | N19: =IF(A19="","","oeuvres/"&A19&".md") -> oeuvres/la-chambre-a-arles.md | O19: à rédiger | P19: =IF(C19="","",IFERROR(INDEX(Artistes!$M$2:$M$301,MATCH(C19,Artistes!$A$2:$A$301,0)),"")) -> Oui (à vérifier) | Q19: Fusion de « La chambre à Arles » et « La chambre à coucher » : c'est la même œuvre (trois versions, 1888-1889).
A20: la-nuit-etoilee | B20: La Nuit étoilée | C20: van-gogh | D20: =IF(C20="","",IFERROR(INDEX(Artistes!$B$2:$B$301,MATCH(C20,Artistes!$A$2:$A$301,0)),"ID inconnu")) -> Vincent van Gogh | E20: 1889 | F20: post-impressionnisme | H20: peinture | I20: MoMA | J20: New York | K20: oui | N20: =IF(A20="","","oeuvres/"&A20&".md") -> oeuvres/la-nuit-etoilee.md | O20: à rédiger | P20: =IF(C20="","",IFERROR(INDEX(Artistes!$M$2:$M$301,MATCH(C20,Artistes!$A$2:$A$301,0)),"")) -> Oui (à vérifier)
A21: les-joueurs-de-cartes | B21: Les Joueurs de cartes | C21: cezanne | D21: =IF(C21="","",IFERROR(INDEX(Artistes!$B$2:$B$301,MATCH(C21,Artistes!$A$2:$A$301,0)),"ID inconnu")) -> Paul Cézanne | E21: 1892 | F21: post-impressionnisme | G21: série, 1890-1895 | H21: peinture | I21: Musée d'Orsay (une version) | J21: Paris | N21: =IF(A21="","","oeuvres/"&A21&".md") -> oeuvres/les-joueurs-de-cartes.md | O21: à rédiger | P21: =IF(C21="","",IFERROR(INDEX(Artistes!$M$2:$M$301,MATCH(C21,Artistes!$A$2:$A$301,0)),"")) -> Oui (à vérifier)
A22: la-corbeille-de-pommes | B22: La Corbeille de pommes | C22: cezanne | D22: =IF(C22="","",IFERROR(INDEX(Artistes!$B$2:$B$301,MATCH(C22,Artistes!$A$2:$A$301,0)),"ID inconnu")) -> Paul Cézanne | E22: 1894 | F22: post-impressionnisme | G22: vers 1893 | H22: peinture | I22: Art Institute of Chicago | J22: Chicago | N22: =IF(A22="","","oeuvres/"&A22&".md") -> oeuvres/la-corbeille-de-pommes.md | O22: à rédiger | P22: =IF(C22="","",IFERROR(INDEX(Artistes!$M$2:$M$301,MATCH(C22,Artistes!$A$2:$A$301,0)),"")) -> Oui (à vérifier)
A23: la-montagne-sainte-victoire | B23: La Montagne Sainte-Victoire | C23: cezanne | D23: =IF(C23="","",IFERROR(INDEX(Artistes!$B$2:$B$301,MATCH(C23,Artistes!$A$2:$A$301,0)),"ID inconnu")) -> Paul Cézanne | E23: 1885 | F23: post-impressionnisme | G23: série, 1885-1906 | H23: peinture | N23: =IF(A23="","","oeuvres/"&A23&".md") -> oeuvres/la-montagne-sainte-victoire.md | O23: à rédiger | P23: =IF(C23="","",IFERROR(INDEX(Artistes!$M$2:$M$301,MATCH(C23,Artistes!$A$2:$A$301,0)),"")) -> Oui (à vérifier)
A24: les-grandes-baigneuses | B24: Les Grandes Baigneuses | C24: cezanne | D24: =IF(C24="","",IFERROR(INDEX(Artistes!$B$2:$B$301,MATCH(C24,Artistes!$A$2:$A$301,0)),"ID inconnu")) -> Paul Cézanne | E24: 1905 | F24: post-impressionnisme | G24: 1898-1905 | H24: peinture | I24: Philadelphia Museum of Art | J24: Philadelphie | K24: oui | N24: =IF(A24="","","oeuvres/"&A24&".md") -> oeuvres/les-grandes-baigneuses.md | O24: à rédiger | P24: =IF(C24="","",IFERROR(INDEX(Artistes!$M$2:$M$301,MATCH(C24,Artistes!$A$2:$A$301,0)),"")) -> Oui (à vérifier) | Q24: Ta fiche Cézanne dit 1898, ta liste d'œuvres majeures 1898-1905 : harmonisé.
A25: joyeusetes-arearea | B25: Joyeusetés (Arearea) | C25: gauguin | D25: =IF(C25="","",IFERROR(INDEX(Artistes!$B$2:$B$301,MATCH(C25,Artistes!$A$2:$A$301,0)),"ID inconnu")) -> Paul Gauguin | E25: 1892 | F25: post-impressionnisme | H25: peinture | I25: Musée d'Orsay | J25: Paris | N25: =IF(A25="","","oeuvres/"&A25&".md") -> oeuvres/joyeusetes-arearea.md | O25: à rédiger | P25: =IF(C25="","",IFERROR(INDEX(Artistes!$M$2:$M$301,MATCH(C25,Artistes!$A$2:$A$301,0)),"")) -> Oui (à vérifier)
A26: jour-de-dieu-mahana-no-atua | B26: Jour de Dieu (Mahana no atua) | C26: gauguin | D26: =IF(C26="","",IFERROR(INDEX(Artistes!$B$2:$B$301,MATCH(C26,Artistes!$A$2:$A$301,0)),"ID inconnu")) -> Paul Gauguin | E26: 1894 | F26: post-impressionnisme | H26: peinture | I26: Art Institute of Chicago | J26: Chicago | N26: =IF(A26="","","oeuvres/"&A26&".md") -> oeuvres/jour-de-dieu-mahana-no-atua.md | O26: à rédiger | P26: =IF(C26="","",IFERROR(INDEX(Artistes!$M$2:$M$301,MATCH(C26,Artistes!$A$2:$A$301,0)),"")) -> Oui (à vérifier)
A27: d-ou-venons-nous-que-sommes-nous-ou | B27: D'où venons-nous ? Que sommes-nous ? Où allons-nous ? | C27: gauguin | D27: =IF(C27="","",IFERROR(INDEX(Artistes!$B$2:$B$301,MATCH(C27,Artistes!$A$2:$A$301,0)),"ID inconnu")) -> Paul Gauguin | E27: 1898 | F27: post-impressionnisme | G27: 1897-1898 | H27: peinture | I27: Museum of Fine Arts | J27: Boston | K27: oui | N27: =IF(A27="","","oeuvres/"&A27&".md") -> oeuvres/d-ou-venons-nous-que-sommes-nous-ou.md | O27: à rédiger | P27: =IF(C27="","",IFERROR(INDEX(Artistes!$M$2:$M$301,MATCH(C27,Artistes!$A$2:$A$301,0)),"")) -> Oui (à vérifier) | Q27: Ta liste d'œuvres majeures écrit « Qui sommes-nous » : le titre exact est « Que sommes-nous ».
A28: une-baignade-a-asnieres | B28: Une baignade à Asnières | C28: seurat | D28: =IF(C28="","",IFERROR(INDEX(Artistes!$B$2:$B$301,MATCH(C28,Artistes!$A$2:$A$301,0)),"ID inconnu")) -> Georges Seurat | E28: 1884 | F28: post-impressionnisme | H28: peinture | I28: National Gallery | J28: Londres | N28: =IF(A28="","","oeuvres/"&A28&".md") -> oeuvres/une-baignade-a-asnieres.md | O28: à rédiger | P28: =IF(C28="","",IFERROR(INDEX(Artistes!$M$2:$M$301,MATCH(C28,Artistes!$A$2:$A$301,0)),"")) -> Oui (à vérifier) | Q28: Erreur corrigée : ta Bible dit 1894, or Seurat meurt en 1891. L'œuvre date de 1884.
A29: un-dimanche-apres-midi-a-l-ile-de-la | B29: Un dimanche après-midi à l'île de la Grande Jatte | C29: seurat | D29: =IF(C29="","",IFERROR(INDEX(Artistes!$B$2:$B$301,MATCH(C29,Artistes!$A$2:$A$301,0)),"ID inconnu")) -> Georges Seurat | E29: 1886 | F29: post-impressionnisme | G29: 1884-1886 | H29: peinture | I29: Art Institute of Chicago | J29: Chicago | K29: oui | N29: =IF(A29="","","oeuvres/"&A29&".md") -> oeuvres/un-dimanche-apres-midi-a-l-ile-de-la.md | O29: à rédiger | P29: =IF(C29="","",IFERROR(INDEX(Artistes!$M$2:$M$301,MATCH(C29,Artistes!$A$2:$A$301,0)),"")) -> Oui (à vérifier)
A30: le-cirque | B30: Le Cirque | C30: seurat | D30: =IF(C30="","",IFERROR(INDEX(Artistes!$B$2:$B$301,MATCH(C30,Artistes!$A$2:$A$301,0)),"ID inconnu")) -> Georges Seurat | E30: 1891 | F30: post-impressionnisme | G30: 1890-1891 | H30: peinture | I30: Musée d'Orsay | J30: Paris | N30: =IF(A30="","","oeuvres/"&A30&".md") -> oeuvres/le-cirque.md | O30: à rédiger | P30: =IF(C30="","",IFERROR(INDEX(Artistes!$M$2:$M$301,MATCH(C30,Artistes!$A$2:$A$301,0)),"")) -> Oui (à vérifier)
A31: la-femme-au-chapeau | B31: La Femme au chapeau | C31: matisse | D31: =IF(C31="","",IFERROR(INDEX(Artistes!$B$2:$B$301,MATCH(C31,Artistes!$A$2:$A$301,0)),"ID inconnu")) -> Henri Matisse | E31: 1905 | F31: fauvisme | H31: peinture | I31: SFMOMA | J31: San Francisco | N31: =IF(A31="","","oeuvres/"&A31&".md") -> oeuvres/la-femme-au-chapeau.md | O31: à rédiger | P31: =IF(C31="","",IFERROR(INDEX(Artistes!$M$2:$M$301,MATCH(C31,Artistes!$A$2:$A$301,0)),"")) -> Oui (à vérifier)
A32: la-danse-matisse | B32: La Danse | C32: matisse | D32: =IF(C32="","",IFERROR(INDEX(Artistes!$B$2:$B$301,MATCH(C32,Artistes!$A$2:$A$301,0)),"ID inconnu")) -> Henri Matisse | E32: 1910 | F32: fauvisme | H32: peinture | I32: Musée de l'Ermitage | J32: Saint-Pétersbourg | K32: oui | N32: =IF(A32="","","oeuvres/"&A32&".md") -> oeuvres/la-danse-matisse.md | O32: à rédiger | P32: =IF(C32="","",IFERROR(INDEX(Artistes!$M$2:$M$301,MATCH(C32,Artistes!$A$2:$A$301,0)),"")) -> Oui (à vérifier)
A33: l-atelier-rouge | B33: L'Atelier rouge | C33: matisse | D33: =IF(C33="","",IFERROR(INDEX(Artistes!$B$2:$B$301,MATCH(C33,Artistes!$A$2:$A$301,0)),"ID inconnu")) -> Henri Matisse | E33: 1911 | F33: fauvisme | H33: peinture | I33: MoMA | J33: New York | K33: oui | N33: =IF(A33="","","oeuvres/"&A33&".md") -> oeuvres/l-atelier-rouge.md | O33: à rédiger | P33: =IF(C33="","",IFERROR(INDEX(Artistes!$M$2:$M$301,MATCH(C33,Artistes!$A$2:$A$301,0)),"")) -> Oui (à vérifier)
A34: les-odalisques | B34: Les Odalisques | C34: matisse | D34: =IF(C34="","",IFERROR(INDEX(Artistes!$B$2:$B$301,MATCH(C34,Artistes!$A$2:$A$301,0)),"ID inconnu")) -> Henri Matisse | E34: 1925 | F34: fauvisme | G34: série, années 1920 | H34: peinture | N34: =IF(A34="","","oeuvres/"&A34&".md") -> oeuvres/les-odalisques.md | O34: à rédiger | P34: =IF(C34="","",IFERROR(INDEX(Artistes!$M$2:$M$301,MATCH(C34,Artistes!$A$2:$A$301,0)),"")) -> Oui (à vérifier) | Q34: Postérieure au fauvisme : à garder ou non.
A35: jazz | B35: Jazz | C35: matisse | D35: =IF(C35="","",IFERROR(INDEX(Artistes!$B$2:$B$301,MATCH(C35,Artistes!$A$2:$A$301,0)),"ID inconnu")) -> Henri Matisse | E35: 1947 | F35: fauvisme | H35: livre (papiers découpés) | N35: =IF(A35="","","oeuvres/"&A35&".md") -> oeuvres/jazz.md | O35: à rédiger | P35: =IF(C35="","",IFERROR(INDEX(Artistes!$M$2:$M$301,MATCH(C35,Artistes!$A$2:$A$301,0)),"")) -> Oui (à vérifier) | Q35: Postérieure au fauvisme : à garder ou non.
A36: nus-bleus | B36: Nus bleus | C36: matisse | D36: =IF(C36="","",IFERROR(INDEX(Artistes!$B$2:$B$301,MATCH(C36,Artistes!$A$2:$A$301,0)),"ID inconnu")) -> Henri Matisse | E36: 1952 | F36: fauvisme | G36: série de quatre, 1952 | H36: gouache découpée | N36: =IF(A36="","","oeuvres/"&A36&".md") -> oeuvres/nus-bleus.md | O36: à rédiger | P36: =IF(C36="","",IFERROR(INDEX(Artistes!$M$2:$M$301,MATCH(C36,Artistes!$A$2:$A$301,0)),"")) -> Oui (à vérifier) | Q36: Postérieure au fauvisme ; ce sont des gouaches découpées, pas des tableaux.
A37: bateaux-dans-le-port-de-collioure | B37: Bateaux dans le port de Collioure | C37: derain | D37: =IF(C37="","",IFERROR(INDEX(Artistes!$B$2:$B$301,MATCH(C37,Artistes!$A$2:$A$301,0)),"ID inconnu")) -> André Derain | E37: 1905 | F37: fauvisme | H37: peinture | K37: oui | N37: =IF(A37="","","oeuvres/"&A37&".md") -> oeuvres/bateaux-dans-le-port-de-collioure.md | O37: à rédiger | P37: =IF(C37="","",IFERROR(INDEX(Artistes!$M$2:$M$301,MATCH(C37,Artistes!$A$2:$A$301,0)),"")) -> Oui (à vérifier)
A38: big-ben | B38: Big Ben | C38: derain | D38: =IF(C38="","",IFERROR(INDEX(Artistes!$B$2:$B$301,MATCH(C38,Artistes!$A$2:$A$301,0)),"ID inconnu")) -> André Derain | E38: 1906 | F38: fauvisme | H38: peinture | N38: =IF(A38="","","oeuvres/"&A38&".md") -> oeuvres/big-ben.md | O38: à rédiger | P38: =IF(C38="","",IFERROR(INDEX(Artistes!$M$2:$M$301,MATCH(C38,Artistes!$A$2:$A$301,0)),"")) -> Oui (à vérifier)
A39: la-danse-derain | B39: La Danse | C39: derain | D39: =IF(C39="","",IFERROR(INDEX(Artistes!$B$2:$B$301,MATCH(C39,Artistes!$A$2:$A$301,0)),"ID inconnu")) -> André Derain | E39: 1906 | F39: fauvisme | H39: peinture | N39: =IF(A39="","","oeuvres/"&A39&".md") -> oeuvres/la-danse-derain.md | O39: à rédiger | P39: =IF(C39="","",IFERROR(INDEX(Artistes!$M$2:$M$301,MATCH(C39,Artistes!$A$2:$A$301,0)),"")) -> Oui (à vérifier)
A40: restaurant-de-la-machine-a-bougival | B40: Restaurant de la Machine à Bougival | C40: vlaminck | D40: =IF(C40="","",IFERROR(INDEX(Artistes!$B$2:$B$301,MATCH(C40,Artistes!$A$2:$A$301,0)),"ID inconnu")) -> Maurice de Vlaminck | E40: 1905 | F40: fauvisme | H40: peinture | I40: Musée d'Orsay | J40: Paris | K40: oui | N40: =IF(A40="","","oeuvres/"&A40&".md") -> oeuvres/restaurant-de-la-machine-a-bougival.md | O40: à rédiger | P40: =IF(C40="","",IFERROR(INDEX(Artistes!$M$2:$M$301,MATCH(C40,Artistes!$A$2:$A$301,0)),"")) -> Non
...

Sheet Événements
A1: ID | B1: Année | C1: Date précise | D1: Titre | E1: Lieu | F1: Mouvement | G1: Description (1-2 phrases) | H1: Notes / corrections
A2: salon-des-refuses | B2: 1863 | C2: mai 1863 | D2: Salon des refusés | E2: Paris | F2: impressionnisme | H2: Hors périmètre : prologue, à garder ou supprimer.
A3: premiere-expo-impressionniste | B3: 1874 | C3: 15 avril 1874 | D3: Première exposition impressionniste | E3: Paris | F3: impressionnisme
A4: durand-ruel-new-york | B4: 1886 | C4: avril 1886 | D4: Durand-Ruel expose les impressionnistes à New York | E4: New York | F4: impressionnisme
A5: derniere-expo-impressionniste | B5: 1886 | C5: mai 1886 | D5: Huitième et dernière exposition impressionniste | E5: Paris | F5: impressionnisme
A6: cage-aux-fauves | B6: 1905 | C6: octobre 1905 | D6: Salon d'automne : la « cage aux fauves » | E6: Paris | F6: fauvisme
A7: fondation-die-brucke | B7: 1905 | C7: juin 1905 | D7: Fondation de Die Brücke | E7: Dresde | F7: expressionnisme
A8: retrospective-cezanne | B8: 1907 | C8: octobre 1907 | D8: Rétrospective Cézanne au Salon d'automne | E8: Paris | F8: cubisme
A9: expo-blaue-reiter | B9: 1911 | C9: décembre 1911 | D9: Première exposition du Blaue Reiter | E9: Munich | F9: expressionnisme
A10: armory-show | B10: 1913 | C10: février 1913 | D10: Armory Show | E10: New York | F10: cubisme
A11: expo-0-10 | B11: 1915 | C11: décembre 1915 | D11: Exposition « 0,10 » : Malevitch montre le Carré noir | E11: Petrograd | F11: abstraction
A12: cabaret-voltaire | B12: 1916 | C12: février 1916 | D12: Ouverture du Cabaret Voltaire | E12: Zurich | F12: dadaisme
A13: manifeste-surrealisme | B13: 1924 | C13: octobre 1924 | D13: Publication du Manifeste du surréalisme | E13: Paris | F13: surrealisme
A14: art-degenere | B14: 1937 | C14: juillet 1937 | D14: Exposition nazie « Art dégénéré » | E14: Munich | F14: expressionnisme
A15: art-of-this-century | B15: 1942 | C15: octobre 1942 | D15: Peggy Guggenheim ouvre la galerie Art of This Century | E15: New York | F15: expressionnisme-abstrait

Sheet Influences
A1: ID | B1: De (ID) | C1: De | D1: Vers (ID) | E1: Vers | F1: Type | G1: Explication (1-2 phrases) | H1: Notes / corrections
A2: cezanne-picasso | B2: cezanne | C2: =IF(B2="","",IFERROR(INDEX(Artistes!$B$2:$B$301,MATCH(B2,Artistes!$A$2:$A$301,0)),"ID inconnu")) -> Paul Cézanne | D2: picasso | E2: =IF(D2="","",IFERROR(INDEX(Artistes!$B$2:$B$301,MATCH(D2,Artistes!$A$2:$A$301,0)),"ID inconnu")) -> Pablo Picasso | F2: influence
A3: cezanne-braque | B3: cezanne | C3: =IF(B3="","",IFERROR(INDEX(Artistes!$B$2:$B$301,MATCH(B3,Artistes!$A$2:$A$301,0)),"ID inconnu")) -> Paul Cézanne | D3: braque | E3: =IF(D3="","",IFERROR(INDEX(Artistes!$B$2:$B$301,MATCH(D3,Artistes!$A$2:$A$301,0)),"ID inconnu")) -> Georges Braque | F3: influence
A4: van-gogh-vlaminck | B4: van-gogh | C4: =IF(B4="","",IFERROR(INDEX(Artistes!$B$2:$B$301,MATCH(B4,Artistes!$A$2:$A$301,0)),"ID inconnu")) -> Vincent van Gogh | D4: vlaminck | E4: =IF(D4="","",IFERROR(INDEX(Artistes!$B$2:$B$301,MATCH(D4,Artistes!$A$2:$A$301,0)),"ID inconnu")) -> Maurice de Vlaminck | F4: influence
A5: van-gogh-kirchner | B5: van-gogh | C5: =IF(B5="","",IFERROR(INDEX(Artistes!$B$2:$B$301,MATCH(B5,Artistes!$A$2:$A$301,0)),"ID inconnu")) -> Vincent van Gogh | D5: kirchner | E5: =IF(D5="","",IFERROR(INDEX(Artistes!$B$2:$B$301,MATCH(D5,Artistes!$A$2:$A$301,0)),"ID inconnu")) -> Ernst Ludwig Kirchner | F5: influence
A6: gauguin-matisse | B6: gauguin | C6: =IF(B6="","",IFERROR(INDEX(Artistes!$B$2:$B$301,MATCH(B6,Artistes!$A$2:$A$301,0)),"ID inconnu")) -> Paul Gauguin | D6: matisse | E6: =IF(D6="","",IFERROR(INDEX(Artistes!$B$2:$B$301,MATCH(D6,Artistes!$A$2:$A$301,0)),"ID inconnu")) -> Henri Matisse | F6: influence
A7: matisse-derain | B7: matisse | C7: =IF(B7="","",IFERROR(INDEX(Artistes!$B$2:$B$301,MATCH(B7,Artistes!$A$2:$A$301,0)),"ID inconnu")) -> Henri Matisse | D7: derain | E7: =IF(D7="","",IFERROR(INDEX(Artistes!$B$2:$B$301,MATCH(D7,Artistes!$A$2:$A$301,0)),"ID inconnu")) -> André Derain | F7: collaboration
A8: picasso-braque | B8: picasso | C8: =IF(B8="","",IFERROR(INDEX(Artistes!$B$2:$B$301,MATCH(B8,Artistes!$A$2:$A$301,0)),"ID inconnu")) -> Pablo Picasso | D8: braque | E8: =IF(D8="","",IFERROR(INDEX(Artistes!$B$2:$B$301,MATCH(D8,Artistes!$A$2:$A$301,0)),"ID inconnu")) -> Georges Braque | F8: collaboration
A9: monet-kandinsky | B9: monet | C9: =IF(B9="","",IFERROR(INDEX(Artistes!$B$2:$B$301,MATCH(B9,Artistes!$A$2:$A$301,0)),"ID inconnu")) -> Claude Monet | D9: kandinsky | E9: =IF(D9="","",IFERROR(INDEX(Artistes!$B$2:$B$301,MATCH(D9,Artistes!$A$2:$A$301,0)),"ID inconnu")) -> Vassily Kandinsky | F9: influence
A10: kandinsky-marc | B10: kandinsky | C10: =IF(B10="","",IFERROR(INDEX(Artistes!$B$2:$B$301,MATCH(B10,Artistes!$A$2:$A$301,0)),"ID inconnu")) -> Vassily Kandinsky | D10: marc | E10: =IF(D10="","",IFERROR(INDEX(Artistes!$B$2:$B$301,MATCH(D10,Artistes!$A$2:$A$301,0)),"ID inconnu")) -> Franz Marc | F10: collaboration
A11: picabia-duchamp | B11: picabia | C11: =IF(B11="","",IFERROR(INDEX(Artistes!$B$2:$B$301,MATCH(B11,Artistes!$A$2:$A$301,0)),"ID inconnu")) -> Francis Picabia | D11: duchamp | E11: =IF(D11="","",IFERROR(INDEX(Artistes!$B$2:$B$301,MATCH(D11,Artistes!$A$2:$A$301,0)),"ID inconnu")) -> Marcel Duchamp | F11: collaboration
A12: tzara-breton | B12: tzara | C12: =IF(B12="","",IFERROR(INDEX(Artistes!$B$2:$B$301,MATCH(B12,Artistes!$A$2:$A$301,0)),"ID inconnu")) -> Tristan Tzara | D12: breton | E12: =IF(D12="","",IFERROR(INDEX(Artistes!$B$2:$B$301,MATCH(D12,Artistes!$A$2:$A$301,0)),"ID inconnu")) -> André Breton | F12: rivalité
A13: matisse-rothko | B13: matisse | C13: =IF(B13="","",IFERROR(INDEX(Artistes!$B$2:$B$301,MATCH(B13,Artistes!$A$2:$A$301,0)),"ID inconnu")) -> Henri Matisse | D13: rothko | E13: =IF(D13="","",IFERROR(INDEX(Artistes!$B$2:$B$301,MATCH(D13,Artistes!$A$2:$A$301,0)),"ID inconnu")) -> Mark Rothko | F13: influence
C14: =IF(B14="","",IFERROR(INDEX(Artistes!$B$2:$B$301,MATCH(B14,Artistes!$A$2:$A$301,0)),"ID inconnu")) | E14: =IF(D14="","",IFERROR(INDEX(Artistes!$B$2:$B$301,MATCH(D14,Artistes!$A$2:$A$301,0)),"ID inconnu"))
C15: =IF(B15="","",IFERROR(INDEX(Artistes!$B$2:$B$301,MATCH(B15,Artistes!$A$2:$A$301,0)),"ID inconnu")) | E15: =IF(D15="","",IFERROR(INDEX(Artistes!$B$2:$B$301,MATCH(D15,Artistes!$A$2:$A$301,0)),"ID inconnu"))
C16: =IF(B16="","",IFERROR(INDEX(Artistes!$B$2:$B$301,MATCH(B16,Artistes!$A$2:$A$301,0)),"ID inconnu")) | E16: =IF(D16="","",IFERROR(INDEX(Artistes!$B$2:$B$301,MATCH(D16,Artistes!$A$2:$A$301,0)),"ID inconnu"))
C17: =IF(B17="","",IFERROR(INDEX(Artistes!$B$2:$B$301,MATCH(B17,Artistes!$A$2:$A$301,0)),"ID inconnu")) | E17: =IF(D17="","",IFERROR(INDEX(Artistes!$B$2:$B$301,MATCH(D17,Artistes!$A$2:$A$301,0)),"ID inconnu"))
C18: =IF(B18="","",IFERROR(INDEX(Artistes!$B$2:$B$301,MATCH(B18,Artistes!$A$2:$A$301,0)),"ID inconnu")) | E18: =IF(D18="","",IFERROR(INDEX(Artistes!$B$2:$B$301,MATCH(D18,Artistes!$A$2:$A$301,0)),"ID inconnu"))
C19: =IF(B19="","",IFERROR(INDEX(Artistes!$B$2:$B$301,MATCH(B19,Artistes!$A$2:$A$301,0)),"ID inconnu")) | E19: =IF(D19="","",IFERROR(INDEX(Artistes!$B$2:$B$301,MATCH(D19,Artistes!$A$2:$A$301,0)),"ID inconnu"))
C20: =IF(B20="","",IFERROR(INDEX(Artistes!$B$2:$B$301,MATCH(B20,Artistes!$A$2:$A$301,0)),"ID inconnu")) | E20: =IF(D20="","",IFERROR(INDEX(Artistes!$B$2:$B$301,MATCH(D20,Artistes!$A$2:$A$301,0)),"ID inconnu"))
C21: =IF(B21="","",IFERROR(INDEX(Artistes!$B$2:$B$301,MATCH(B21,Artistes!$A$2:$A$301,0)),"ID inconnu")) | E21: =IF(D21="","",IFERROR(INDEX(Artistes!$B$2:$B$301,MATCH(D21,Artistes!$A$2:$A$301,0)),"ID inconnu"))
C22: =IF(B22="","",IFERROR(INDEX(Artistes!$B$2:$B$301,MATCH(B22,Artistes!$A$2:$A$301,0)),"ID inconnu")) | E22: =IF(D22="","",IFERROR(INDEX(Artistes!$B$2:$B$301,MATCH(D22,Artistes!$A$2:$A$301,0)),"ID inconnu"))
C23: =IF(B23="","",IFERROR(INDEX(Artistes!$B$2:$B$301,MATCH(B23,Artistes!$A$2:$A$301,0)),"ID inconnu")) | E23: =IF(D23="","",IFERROR(INDEX(Artistes!$B$2:$B$301,MATCH(D23,Artistes!$A$2:$A$301,0)),"ID inconnu"))
C24: =IF(B24="","",IFERROR(INDEX(Artistes!$B$2:$B$301,MATCH(B24,Artistes!$A$2:$A$301,0)),"ID inconnu")) | E24: =IF(D24="","",IFERROR(INDEX(Artistes!$B$2:$B$301,MATCH(D24,Artistes!$A$2:$A$301,0)),"ID inconnu"))
C25: =IF(B25="","",IFERROR(INDEX(Artistes!$B$2:$B$301,MATCH(B25,Artistes!$A$2:$A$301,0)),"ID inconnu")) | E25: =IF(D25="","",IFERROR(INDEX(Artistes!$B$2:$B$301,MATCH(D25,Artistes!$A$2:$A$301,0)),"ID inconnu"))
... C301: =IF(B301="","",IFERROR(INDEX(Artistes!$B$2:$B$301,MATCH(B301,Artistes!$A$2:$A$301,0)),"ID inconnu")) | E301: =IF(D301="","",IFERROR(INDEX(Artistes!$B$2:$B$301,MATCH(D301,Artistes!$A$2:$A$301,0)),"ID inconnu"))
